/home/lcur0649/.conda/envs/dl2022/lib/python3.10/site-packages/torchvision/models/_utils.py:208: UserWarning: The parameter 'pretrained' is deprecated since 0.13 and may be removed in the future, please use 'weights' instead.
  warnings.warn(
/home/lcur0649/.conda/envs/dl2022/lib/python3.10/site-packages/torchvision/models/_utils.py:223: UserWarning: Arguments other than a weight enum or `None` for 'weights' are deprecated since 0.13 and may be removed in the future. The current behavior is equivalent to passing `weights=ResNet18_Weights.IMAGENET1K_V1`. You can also use `weights=ResNet18_Weights.DEFAULT` to get the most up-to-date weights.
  warnings.warn(msg)
Model Initialized
Parameters to be updated:
"Parameters to be updated: {'fc.bias', 'fc.weight'}"
Traceback (most recent call last):
  File "/home/lcur0649/.conda/envs/dl2022/lib/python3.10/urllib/request.py", line 1348, in do_open
    h.request(req.get_method(), req.selector, req.data, headers,
  File "/home/lcur0649/.conda/envs/dl2022/lib/python3.10/http/client.py", line 1282, in request
    self._send_request(method, url, body, headers, encode_chunked)
  File "/home/lcur0649/.conda/envs/dl2022/lib/python3.10/http/client.py", line 1328, in _send_request
    self.endheaders(body, encode_chunked=encode_chunked)
  File "/home/lcur0649/.conda/envs/dl2022/lib/python3.10/http/client.py", line 1277, in endheaders
    self._send_output(message_body, encode_chunked=encode_chunked)
  File "/home/lcur0649/.conda/envs/dl2022/lib/python3.10/http/client.py", line 1037, in _send_output
    self.send(msg)
  File "/home/lcur0649/.conda/envs/dl2022/lib/python3.10/http/client.py", line 975, in send
    self.connect()
  File "/home/lcur0649/.conda/envs/dl2022/lib/python3.10/http/client.py", line 1447, in connect
    super().connect()
  File "/home/lcur0649/.conda/envs/dl2022/lib/python3.10/http/client.py", line 941, in connect
    self.sock = self._create_connection(
  File "/home/lcur0649/.conda/envs/dl2022/lib/python3.10/socket.py", line 845, in create_connection
    raise err
  File "/home/lcur0649/.conda/envs/dl2022/lib/python3.10/socket.py", line 833, in create_connection
    sock.connect(sa)
TimeoutError: [Errno 110] Connection timed out

During handling of the above exception, another exception occurred:

Traceback (most recent call last):
  File "/home/lcur0649/uvadlc_practicals_2022/assignment2/part1/.//train.py", line 281, in <module>
    main(**kwargs)
  File "/home/lcur0649/uvadlc_practicals_2022/assignment2/part1/.//train.py", line 246, in main
    model = train_model(model, lr, batch_size, epochs, data_dir, 'best_model', device, augmentation_name)
  File "/home/lcur0649/uvadlc_practicals_2022/assignment2/part1/.//train.py", line 104, in train_model
    train_set, val_set = get_train_validation_set(data_dir)
  File "/home/lcur0649/uvadlc_practicals_2022/assignment2/part1/cifar100_utils.py", line 76, in get_train_validation_set
    train_dataset = CIFAR100(root=data_dir, train=True, download=True, transform=train_transform)
  File "/home/lcur0649/.conda/envs/dl2022/lib/python3.10/site-packages/torchvision/datasets/cifar.py", line 65, in __init__
    self.download()
  File "/home/lcur0649/.conda/envs/dl2022/lib/python3.10/site-packages/torchvision/datasets/cifar.py", line 139, in download
    download_and_extract_archive(self.url, self.root, filename=self.filename, md5=self.tgz_md5)
  File "/home/lcur0649/.conda/envs/dl2022/lib/python3.10/site-packages/torchvision/datasets/utils.py", line 447, in download_and_extract_archive
    download_url(url, download_root, filename, md5)
  File "/home/lcur0649/.conda/envs/dl2022/lib/python3.10/site-packages/torchvision/datasets/utils.py", line 147, in download_url
    url = _get_redirect_url(url, max_hops=max_redirect_hops)
  File "/home/lcur0649/.conda/envs/dl2022/lib/python3.10/site-packages/torchvision/datasets/utils.py", line 95, in _get_redirect_url
    with urllib.request.urlopen(urllib.request.Request(url, headers=headers)) as response:
  File "/home/lcur0649/.conda/envs/dl2022/lib/python3.10/urllib/request.py", line 216, in urlopen
    return opener.open(url, data, timeout)
  File "/home/lcur0649/.conda/envs/dl2022/lib/python3.10/urllib/request.py", line 519, in open
    response = self._open(req, data)
  File "/home/lcur0649/.conda/envs/dl2022/lib/python3.10/urllib/request.py", line 536, in _open
    result = self._call_chain(self.handle_open, protocol, protocol +
  File "/home/lcur0649/.conda/envs/dl2022/lib/python3.10/urllib/request.py", line 496, in _call_chain
    result = func(*args)
  File "/home/lcur0649/.conda/envs/dl2022/lib/python3.10/urllib/request.py", line 1391, in https_open
    return self.do_open(http.client.HTTPSConnection, req,
  File "/home/lcur0649/.conda/envs/dl2022/lib/python3.10/urllib/request.py", line 1351, in do_open
    raise URLError(err)
urllib.error.URLError: <urlopen error [Errno 110] Connection timed out>
